#VRML_SIM R2020a utf8
WorldInfo {
}
Viewpoint {
  orientation -0.13898572932928513 -0.9434133673400716 -0.3010883348236423 2.340287974984164
  position -8.222077963866811 9.126296609017947 -7.747680074478816
}
TexturedBackground {
}
TexturedBackgroundLight {
}
RectangleArena {
  translation -4.67691 -0.39 0.036
  floorSize 15 10
}
Radiator {
  translation 2.68687 -0.1 1.0606
}
Radiator {
  translation 2.68687 -0.1 -0.9994
  name "radiator(1)"
}
ComputerMouse {
  translation -2.13968 0.32 1.97033
  rotation 0 1 0 2.35619
  name "computer mouse(2)"
}
ComputerMouse {
  translation -2.79931 0.32 -1.87199
  rotation 0 -1 0 -0.523595307179586
}
ComputerMouse {
  translation 1.89587 0.32 -0.300179
  rotation 0 -1 0 -0.523595307179586
  name "computer mouse(1)"
}
DesktopComputer {
  translation 2.35 -0.39 -0.37
}
DesktopComputer {
  translation -2.68 -0.39 1.67
  name "desktop computer(1)"
}
DesktopComputer {
  translation -2.13 -0.39 -1.91
  rotation 0 1 0 3.14159
  name "desktop computer(2)"
}
Laptop {
  translation 1.78 0.29 -0.0507182
  rotation 0 1 0 -0.523595307179586
}
Keyboard {
  translation -2.59 0.31 1.81
  rotation 0 1 0 -0.523595307179586
}
Keyboard {
  translation 2.20062 0.31 -0.319052
  rotation 0 -1 0 2.87979
  name "keyboard(2)"
}
Keyboard {
  translation -2.49927 0.31 -2.00596
  rotation 0 1 0 -3.1415853071795863
  name "keyboard(1)"
}
Monitor {
  translation -2.15604 0.3 1.61304
  rotation 0 -1 0 -2.3561953071795863
}
Monitor {
  translation 2.24859 0.34 -0.0851268
  rotation 0 1 0 0.261803
  name "monitor(2)"
}
Monitor {
  translation -2.54257 0.29 -1.74215
  rotation 0 1 0 -5.307179586466759e-06
  name "monitor(1)"
}
WoodenChair {
  translation -2.48 -0.4 -2.3
}
WoodenChair {
  translation 1.97 -0.4 -2.42
  name "wooden chair(1)"
}
WoodenChair {
  translation 2.08 -0.39 2.13
  rotation 0 1 0 -2.8797953071795863
  name "wooden chair(2)"
}
WoodenChair {
  translation 0.0123534 -0.39 2.09998
  rotation 0 1 0 2.87979
  name "wooden chair(4)"
}
WoodenChair {
  translation -2.59325 -0.39 2.12648
  rotation 0 -1 0 -2.094395307179586
  name "wooden chair(5)"
}
WoodenChair {
  translation 2.08 -0.39 -0.65
  rotation 0 1 0 -0.261795307179586
  name "wooden chair(3)"
}
Cabinet {
  translation -2.3 -0.86 -1.55
}
Cabinet {
  translation 0.0600015 -1.29 -1.96
  rotation 0 1 0 3.14159
  name "cabinet(2)"
}
Cabinet {
  translation -0.529998 -1.29 -1.96
  rotation 0 1 0 3.14159
  name "cabinet(3)"
}
Cabinet {
  translation -3.07 -0.84 0.910001
  rotation 0 1 0 1.5708
  name "cabinet(1)"
}
Desk {
  translation 0.12 -0.44 0.23
}
Desk {
  translation 0.11 -0.43 -0.47
  name "desk(1)"
}
Desk {
  translation -2.48 -0.41 -1.91
  name "desk(3)"
}
Desk {
  translation -2.46 -0.41 1.71
  name "desk(4)"
}
Desk {
  translation -0.14 -0.41 1.75
  name "desk(5)"
}
Desk {
  translation 2.02 -0.41 -0.24
  name "desk(6)"
}
Desk {
  translation 2.02 -0.41 -2
  name "desk(7)"
}
Desk {
  translation 2.02 -0.41 1.74
  name "desk(8)"
}
Desk {
  translation -0.83 -0.42 -0.12
  rotation 0 1 0 -1.5707953071795862
  name "desk(2)"
}
Solid {
  translation -0.19 0.86 2.58
  children [
    Shape {
      appearance PBRAppearance {
        baseColor 1 0.9 0.6
        metalness 0
      }
      geometry Box {
        size 6 2.5 0.1
      }
    }
  ]
}
Solid {
  translation -0.19 0.87 -2.82
  children [
    Shape {
      appearance PBRAppearance {
        baseColor 1 0.9 0.6
        metalness 0
      }
      geometry Box {
        size 6 2.5 0.1
      }
    }
  ]
  name "solid(2)"
}
Solid {
  translation -9.12 0.86 -2.82
  children [
    Shape {
      appearance PBRAppearance {
        baseColor 1 0.9 0.6
        metalness 0
      }
      geometry Box {
        size 6 2.5 0.1
      }
    }
  ]
  name "solid(7)"
}
Solid {
  translation -9.12 0.86 2.65
  children [
    Shape {
      appearance PBRAppearance {
        baseColor 1 0.9 0.6
        metalness 0
      }
      geometry Box {
        size 6 2.5 0.1
      }
    }
  ]
  name "solid(10)"
}
Solid {
  translation -4.66 0.86 -4.94
  children [
    Shape {
      appearance PBRAppearance {
        baseColor 1 0.9 0.6
        metalness 0
      }
      geometry Box {
        size 15 2.5 0.1
      }
    }
  ]
  name "solid(4)"
}
Solid {
  translation -4.66 0.86 4.74
  children [
    Shape {
      appearance PBRAppearance {
        baseColor 1 0.9 0.6
        metalness 0
      }
      geometry Box {
        size 15 2.5 0.1
      }
    }
  ]
  name "solid(6)"
}
Solid {
  translation 2.79 0.86 -0.38
  rotation 0 1 0 -1.5707953071795862
  children [
    Shape {
      appearance PBRAppearance {
        baseColor 1 0.9 0.6
        metalness 0
      }
      geometry Box {
        size 6 2.5 0.1
      }
    }
  ]
  name "solid(1)"
}
Solid {
  translation -6.14 0.86 2.44
  rotation 0 1 0 -1.5707953071795862
  children [
    Shape {
      appearance PBRAppearance {
        baseColor 1 0.9 0.6
        metalness 0
      }
      geometry Box {
        size 0.5 2.5 0.1
      }
    }
  ]
  name "solid(8)"
}
Solid {
  translation -9.12 0.86 -0.0799998
  rotation 0 1 0 -1.5707953071795862
  children [
    Shape {
      appearance PBRAppearance {
        baseColor 1 0.9 0.6
        metalness 0
      }
      geometry Box {
        size 5.4 2.5 6
      }
    }
  ]
  name "solid(9)"
}
Solid {
  translation -12.08 0.86 -0.08
  rotation 0 1 0 -1.5707953071795862
  children [
    Shape {
      appearance PBRAppearance {
        baseColor 1 0.9 0.6
        metalness 0
      }
      geometry Box {
        size 5.5 2.5 0.1
      }
    }
  ]
  name "solid(14)"
}
Solid {
  translation -3.14 0.86 -1.79
  rotation 0 1 0 -1.5707953071795862
  children [
    Shape {
      appearance PBRAppearance {
        baseColor 1 0.9 0.6
        metalness 0
      }
      geometry Box {
        size 2.1 2.5 0.1
      }
    }
  ]
  name "solid(11)"
}
Solid {
  translation -3.14 1.76 -0.22
  rotation 0 1 0 -1.5707953071795862
  children [
    Shape {
      appearance PBRAppearance {
        baseColor 1 0.9 0.6
        metalness 0
      }
      geometry Box {
        size 2 0.7 0.1
      }
    }
  ]
  name "solid(13)"
}
Solid {
  translation -3.14 0.86 1.33
  rotation 0 1 0 -1.5707953071795862
  children [
    Shape {
      appearance PBRAppearance {
        baseColor 1 0.9 0.6
        metalness 0
      }
      geometry Box {
        size 2.5 2.5 0.1
      }
    }
  ]
  name "solid(12)"
}
Solid {
  translation 2.79 0.86 -1.94
  rotation 0 1 0 -1.5707953071795862
  children [
    Shape {
      appearance PBRAppearance {
        baseColor 1 0.9 0.6
        metalness 0
      }
      geometry Box {
        size 6 2.5 0.1
      }
    }
  ]
  name "solid(3)"
}
Solid {
  translation 2.79 0.86 1.73
  rotation 0 1 0 -1.5707953071795862
  children [
    Shape {
      appearance PBRAppearance {
        baseColor 1 0.9 0.6
        metalness 0
      }
      geometry Box {
        size 6 2.5 0.1
      }
    }
  ]
  name "solid(5)"
}
Robot {
  translation -1.1 -0.35 1.22
  rotation 0 1 0 -2.3561953071795863
  children [
    HingeJoint {
      jointParameters HingeJointParameters {
      }
      endPoint Solid {
        translation 0 0.948144 -0.0600361
        rotation 1 0 0 -0.261795307179586
        children [
          Shape {
            appearance PBRAppearance {
              baseColor 1 1 0
              metalness 0
            }
            geometry Box {
              size 0.4 0.03 0.03
            }
          }
        ]
        name "solid(10)"
      }
    }
    HingeJoint {
      jointParameters HingeJointParameters {
      }
      endPoint Solid {
        translation 0 0.71 0
        rotation 1 0 0 -0.261795307179586
        children [
          Shape {
            appearance PBRAppearance {
              baseColor 1 1 0
              metalness 0
            }
            geometry Box {
              size 0.4 0.03 0.03
            }
          }
        ]
        name "solid(9)"
      }
    }
    DEF display HingeJoint {
      jointParameters HingeJointParameters {
      }
      endPoint Solid {
        translation 0 0.832236 -0.0289778
        rotation 1 0 0 -0.261795307179586
        children [
          Shape {
            appearance PBRAppearance {
              baseColor 1 0 1
            }
            geometry Box {
              size 0.4 0.2 0.01
            }
          }
        ]
        name "solid(8)"
      }
    }
    DEF zadpalka2 HingeJoint {
      jointParameters HingeJointParameters {
      }
      endPoint Solid {
        translation -0.17 0.29 -0.058
        rotation 1 0 0 0.262
        children [
          Shape {
            appearance PBRAppearance {
              baseColor 1 1 0
              metalness 0
            }
            geometry Box {
              size 0.03 0.6 0.03
            }
          }
        ]
        name "solid(7)"
      }
    }
    DEF zadpalka HingeJoint {
      jointParameters HingeJointParameters {
      }
      endPoint Solid {
        translation 0.17 0.29 -0.0579557
        rotation 1 0 0 0.261799
        children [
          Shape {
            appearance PBRAppearance {
              baseColor 1 1 0
              metalness 0
            }
            geometry Box {
              size 0.03 0.6 0.03
            }
          }
        ]
        name "solid(6)"
      }
    }
    DEF palka2 HingeJoint {
      jointParameters HingeJointParameters {
      }
      endPoint Solid {
        translation -0.17 0.48 0.05
        rotation -1 0 0 0.262
        children [
          Shape {
            appearance PBRAppearance {
              baseColor 1 1 0
              metalness 0
            }
            geometry Box {
              size 0.03 1 0.03
            }
          }
        ]
        name "solid(5)"
      }
    }
    DEF palka HingeJoint {
      jointParameters HingeJointParameters {
      }
      endPoint Solid {
        translation 0.17 0.48 0.05
        rotation -1 0 0 0.261795
        children [
          Shape {
            appearance PBRAppearance {
              baseColor 1 1 0
              metalness 0
            }
            geometry Box {
              size 0.03 1 0.03
            }
          }
        ]
        name "solid(4)"
      }
    }
    HingeJoint {
      jointParameters HingeJointParameters {
        anchor 0.21 0 0.05
      }
      device [
        RotationalMotor {
          name "wheel1"
        }
      ]
      endPoint Solid {
        translation 0.21 0 0.05
        rotation 0 0 1 1.57
        children [
          DEF Wheel Shape {
            appearance PBRAppearance {
            }
            geometry Cylinder {
              height 0.02
              radius 0.04
            }
          }
        ]
        boundingObject USE Wheel
        physics DEF physics_wh Physics {
        }
      }
    }
    HingeJoint {
      jointParameters HingeJointParameters {
        anchor -0.21 0 0.05
      }
      device [
        RotationalMotor {
          name "wheel2"
        }
      ]
      endPoint Solid {
        translation -0.21 0 0.05
        rotation 0 0 1 1.57
        children [
          USE Wheel
        ]
        name "solid(1)"
        boundingObject USE Wheel
        physics USE physics_wh
      }
    }
    HingeJoint {
      jointParameters HingeJointParameters {
        anchor 0 0 -0.05
      }
      device [
        RotationalMotor {
          name "wheel3"
        }
      ]
      endPoint Solid {
        translation 0 0 -0.05
        rotation 0 0 1 1.57
        children [
          USE Wheel
        ]
        name "solid(2)"
        boundingObject USE Wheel
        physics USE physics_wh
      }
    }
    HingeJoint {
      jointParameters HingeJointParameters {
        anchor 0 0 -0.05
      }
      device [
        RotationalMotor {
          name "wheel4"
        }
      ]
      endPoint Solid {
        translation 0 0 -0.05
        rotation 0 0 1 1.57
        children [
          USE Wheel
        ]
        name "solid(3)"
        boundingObject USE Wheel
        physics USE physics_wh
      }
    }
    DistanceSensor {
      translation 0.2 0 0.2
      rotation 0 1 0 -0.7853996938995746
      children [
        DEF sensor Shape {
          appearance PBRAppearance {
            baseColor 0 1 0
          }
          geometry Box {
            size 0.01 0.01 0.01
          }
        }
      ]
      name "ds_left"
      boundingObject USE sensor
      physics Physics {
      }
    }
    DistanceSensor {
      translation -0.2 0 0.2
      rotation 0 1 0 -2.3561996938995744
      children [
        USE sensor
      ]
      name "ds_right"
      boundingObject USE sensor
      physics Physics {
      }
    }
    DEF Body Shape {
      appearance PBRAppearance {
        baseColor 1 0 0
        metalness 0
      }
      geometry Box {
        size 0.4 0.01 0.4
      }
    }
  ]
  boundingObject USE Body
  physics Physics {
  }
  controller "my_controller2"
}
